<?xml version="1.0" encoding="UTF-8"?>
<testsuites name="jest tests" tests="6" failures="4" errors="0" time="0.148">
  <testsuite name="__tests__/main.test.js" errors="0" failures="3" skipped="0" timestamp="2025-09-08T06:35:31" time="0.105" tests="4">
    <testcase classname="Test 1" name="Passing test" time="0.001">
    </testcase>
    <testcase classname="Test 1 › Test 1.1" name="Failing test" time="0.001">
      <failure>Error: expect(received).toBeTruthy()

Received: false
    at Object.toBeTruthy (/Users/noobie_doobie_doo/Desktop/step/maintained-actions/test-reporting/reports/jest/__tests__/main.test.js:10:21)
    at Promise.then.completed (/Users/noobie_doobie_doo/Desktop/step/maintained-actions/test-reporting/reports/jest/node_modules/jest-circus/build/utils.js:298:28)
    at new Promise (&lt;anonymous&gt;)
    at callAsyncCircusFn (/Users/noobie_doobie_doo/Desktop/step/maintained-actions/test-reporting/reports/jest/node_modules/jest-circus/build/utils.js:231:10)
    at _callCircusTest (/Users/noobie_doobie_doo/Desktop/step/maintained-actions/test-reporting/reports/jest/node_modules/jest-circus/build/run.js:316:40)
    at processTicksAndRejections (node:internal/process/task_queues:105:5)
    at _runTest (/Users/noobie_doobie_doo/Desktop/step/maintained-actions/test-reporting/reports/jest/node_modules/jest-circus/build/run.js:252:3)
    at _runTestsForDescribeBlock (/Users/noobie_doobie_doo/Desktop/step/maintained-actions/test-reporting/reports/jest/node_modules/jest-circus/build/run.js:126:9)
    at _runTestsForDescribeBlock (/Users/noobie_doobie_doo/Desktop/step/maintained-actions/test-reporting/reports/jest/node_modules/jest-circus/build/run.js:121:9)
    at _runTestsForDescribeBlock (/Users/noobie_doobie_doo/Desktop/step/maintained-actions/test-reporting/reports/jest/node_modules/jest-circus/build/run.js:121:9)
    at run (/Users/noobie_doobie_doo/Desktop/step/maintained-actions/test-reporting/reports/jest/node_modules/jest-circus/build/run.js:71:3)
    at runAndTransformResultsToJestFormat (/Users/noobie_doobie_doo/Desktop/step/maintained-actions/test-reporting/reports/jest/node_modules/jest-circus/build/legacy-code-todo-rewrite/jestAdapterInit.js:122:21)
    at jestAdapter (/Users/noobie_doobie_doo/Desktop/step/maintained-actions/test-reporting/reports/jest/node_modules/jest-circus/build/legacy-code-todo-rewrite/jestAdapter.js:79:19)
    at runTestInternal (/Users/noobie_doobie_doo/Desktop/step/maintained-actions/test-reporting/reports/jest/node_modules/jest-runner/build/runTest.js:367:16)
    at runTest (/Users/noobie_doobie_doo/Desktop/step/maintained-actions/test-reporting/reports/jest/node_modules/jest-runner/build/runTest.js:444:34)</failure>
    </testcase>
    <testcase classname="Test 1 › Test 1.1" name="Exception in target unit" time="0">
      <failure>Error: Some error
    at Object.throwError (/Users/noobie_doobie_doo/Desktop/step/maintained-actions/test-reporting/reports/jest/lib/main.js:2:9)
    at Object.throwError (/Users/noobie_doobie_doo/Desktop/step/maintained-actions/test-reporting/reports/jest/__tests__/main.test.js:14:11)
    at Promise.then.completed (/Users/noobie_doobie_doo/Desktop/step/maintained-actions/test-reporting/reports/jest/node_modules/jest-circus/build/utils.js:298:28)
    at new Promise (&lt;anonymous&gt;)
    at callAsyncCircusFn (/Users/noobie_doobie_doo/Desktop/step/maintained-actions/test-reporting/reports/jest/node_modules/jest-circus/build/utils.js:231:10)
    at _callCircusTest (/Users/noobie_doobie_doo/Desktop/step/maintained-actions/test-reporting/reports/jest/node_modules/jest-circus/build/run.js:316:40)
    at processTicksAndRejections (node:internal/process/task_queues:105:5)
    at _runTest (/Users/noobie_doobie_doo/Desktop/step/maintained-actions/test-reporting/reports/jest/node_modules/jest-circus/build/run.js:252:3)
    at _runTestsForDescribeBlock (/Users/noobie_doobie_doo/Desktop/step/maintained-actions/test-reporting/reports/jest/node_modules/jest-circus/build/run.js:126:9)
    at _runTestsForDescribeBlock (/Users/noobie_doobie_doo/Desktop/step/maintained-actions/test-reporting/reports/jest/node_modules/jest-circus/build/run.js:121:9)
    at _runTestsForDescribeBlock (/Users/noobie_doobie_doo/Desktop/step/maintained-actions/test-reporting/reports/jest/node_modules/jest-circus/build/run.js:121:9)
    at run (/Users/noobie_doobie_doo/Desktop/step/maintained-actions/test-reporting/reports/jest/node_modules/jest-circus/build/run.js:71:3)
    at runAndTransformResultsToJestFormat (/Users/noobie_doobie_doo/Desktop/step/maintained-actions/test-reporting/reports/jest/node_modules/jest-circus/build/legacy-code-todo-rewrite/jestAdapterInit.js:122:21)
    at jestAdapter (/Users/noobie_doobie_doo/Desktop/step/maintained-actions/test-reporting/reports/jest/node_modules/jest-circus/build/legacy-code-todo-rewrite/jestAdapter.js:79:19)
    at runTestInternal (/Users/noobie_doobie_doo/Desktop/step/maintained-actions/test-reporting/reports/jest/node_modules/jest-runner/build/runTest.js:367:16)
    at runTest (/Users/noobie_doobie_doo/Desktop/step/maintained-actions/test-reporting/reports/jest/node_modules/jest-runner/build/runTest.js:444:34)</failure>
    </testcase>
    <testcase classname="Test 2" name="Exception in test" time="0">
      <failure>Error: Some error
    at Object.&lt;anonymous&gt; (/Users/noobie_doobie_doo/Desktop/step/maintained-actions/test-reporting/reports/jest/__tests__/main.test.js:21:11)
    at Promise.then.completed (/Users/noobie_doobie_doo/Desktop/step/maintained-actions/test-reporting/reports/jest/node_modules/jest-circus/build/utils.js:298:28)
    at new Promise (&lt;anonymous&gt;)
    at callAsyncCircusFn (/Users/noobie_doobie_doo/Desktop/step/maintained-actions/test-reporting/reports/jest/node_modules/jest-circus/build/utils.js:231:10)
    at _callCircusTest (/Users/noobie_doobie_doo/Desktop/step/maintained-actions/test-reporting/reports/jest/node_modules/jest-circus/build/run.js:316:40)
    at processTicksAndRejections (node:internal/process/task_queues:105:5)
    at _runTest (/Users/noobie_doobie_doo/Desktop/step/maintained-actions/test-reporting/reports/jest/node_modules/jest-circus/build/run.js:252:3)
    at _runTestsForDescribeBlock (/Users/noobie_doobie_doo/Desktop/step/maintained-actions/test-reporting/reports/jest/node_modules/jest-circus/build/run.js:126:9)
    at _runTestsForDescribeBlock (/Users/noobie_doobie_doo/Desktop/step/maintained-actions/test-reporting/reports/jest/node_modules/jest-circus/build/run.js:121:9)
    at run (/Users/noobie_doobie_doo/Desktop/step/maintained-actions/test-reporting/reports/jest/node_modules/jest-circus/build/run.js:71:3)
    at runAndTransformResultsToJestFormat (/Users/noobie_doobie_doo/Desktop/step/maintained-actions/test-reporting/reports/jest/node_modules/jest-circus/build/legacy-code-todo-rewrite/jestAdapterInit.js:122:21)
    at jestAdapter (/Users/noobie_doobie_doo/Desktop/step/maintained-actions/test-reporting/reports/jest/node_modules/jest-circus/build/legacy-code-todo-rewrite/jestAdapter.js:79:19)
    at runTestInternal (/Users/noobie_doobie_doo/Desktop/step/maintained-actions/test-reporting/reports/jest/node_modules/jest-runner/build/runTest.js:367:16)
    at runTest (/Users/noobie_doobie_doo/Desktop/step/maintained-actions/test-reporting/reports/jest/node_modules/jest-runner/build/runTest.js:444:34)</failure>
    </testcase>
  </testsuite>
  <testsuite name="__tests__/second.test.js" errors="0" failures="1" skipped="1" timestamp="2025-09-08T06:35:31" time="0.022" tests="2">
    <testcase classname="" name="Timeout test" time="0.003">
      <failure>Error: thrown: &quot;Exceeded timeout of 1 ms for a test.
Add a timeout value to this test to increase the timeout, if this is a long-running test. See https://jestjs.io/docs/api#testname-fn-timeout.&quot;
    at Object.&lt;anonymous&gt; (/Users/noobie_doobie_doo/Desktop/step/maintained-actions/test-reporting/reports/jest/__tests__/second.test.js:1:34)
    at Runtime._execModule (/Users/noobie_doobie_doo/Desktop/step/maintained-actions/test-reporting/reports/jest/node_modules/jest-runtime/build/index.js:1439:24)
    at Runtime._loadModule (/Users/noobie_doobie_doo/Desktop/step/maintained-actions/test-reporting/reports/jest/node_modules/jest-runtime/build/index.js:1022:12)
    at Runtime.requireModule (/Users/noobie_doobie_doo/Desktop/step/maintained-actions/test-reporting/reports/jest/node_modules/jest-runtime/build/index.js:882:12)
    at jestAdapter (/Users/noobie_doobie_doo/Desktop/step/maintained-actions/test-reporting/reports/jest/node_modules/jest-circus/build/legacy-code-todo-rewrite/jestAdapter.js:77:13)
    at runTestInternal (/Users/noobie_doobie_doo/Desktop/step/maintained-actions/test-reporting/reports/jest/node_modules/jest-runner/build/runTest.js:367:16)
    at runTest (/Users/noobie_doobie_doo/Desktop/step/maintained-actions/test-reporting/reports/jest/node_modules/jest-runner/build/runTest.js:444:34)</failure>
    </testcase>
    <testcase classname="" name="Skipped test" time="0">
      <skipped/>
    </testcase>
  </testsuite>
</testsuites>